Workbook

Sheet Dashboard
A1: JUSTICIAAI - DASHBOARD FINANCIERO
A3: RESUMEN EJECUTIVO - MÉTRICAS CLAVE
A4: Métrica | B4: Año 1 | C4: Año 2 | D4: Año 3 | E4: Growth
A5: ARR | B5: ='Revenue Model'!B43 | C5: ='Revenue Model'!C43 | D5: ='Revenue Model'!D43 | E5: ='Revenue Model'!D45
A6: MRR | B6: ='Revenue Model'!B44 | C6: ='Revenue Model'!C44 | D6: ='Revenue Model'!D44
A7: Usuarios/mes | B7: =Assumptions!C8 | C7: =Assumptions!D8 | D7: =Assumptions!E8
A8: Abogados | B8: =Assumptions!C14 | C8: =Assumptions!D14 | D8: =Assumptions!E14
A9: Gross Margin | B9: ='P&L'!B19 | C9: ='P&L'!C19 | D9: ='P&L'!D19
A10: EBITDA | B10: ='P&L'!B30 | C10: ='P&L'!C30 | D10: ='P&L'!D30
A11: EBITDA Margin | B11: ='P&L'!B31 | C11: ='P&L'!C31 | D11: ='P&L'!D31
A12: LTV/CAC | B12: ='Unit Economics'!B8 | C12: ='Unit Economics'!C8 | D12: ='Unit Economics'!D8
A13: Cash Balance | B13: ='Cash Flow'!B30 | C13: ='Cash Flow'!C30 | D13: ='Cash Flow'!D30
A16: DISTRIBUCIÓN DE INGRESOS - AÑO 3
A17: Stream | B17: Monto | C17: % del Total
A18: Comisiones | B18: ='Revenue Model'!D11 | C18: =B18/'Revenue Model'!D43
A19: Suscripciones | B19: ='Revenue Model'!D21 | C19: =B19/'Revenue Model'!D43
A20: Automatizados | B20: ='Revenue Model'!D29 | C20: =B20/'Revenue Model'!D43
A21: B2B | B21: ='Revenue Model'!D35 | C21: =B21/'Revenue Model'!D43
A22: Partnerships | B22: ='Revenue Model'!D39 | C22: =B22/'Revenue Model'!D43
A23: TOTAL | B23: ='Revenue Model'!D43 | C23: =SUM(C18:C22)
A26: MODELO DINÁMICO: Edita los valores en la hoja "Assumptions" y todo se actualiza automáticamente

Sheet Assumptions
A1: SUPUESTOS DEL MODELO (EDITA ESTOS VALORES)
A2: IMPORTANTE: Cambia estos valores y todas las hojas se actualizarán automáticamente
A4: CRECIMIENTO DE USUARIOS
A5: Métrica | B5: Año 1 | C5: Año 2 | D5: Año 3 | E5: Unidad
A6: Usuarios iniciales | B6: 100 | C6: 2000 | D6: 10000 | E6: usuarios
A7: Crecimiento mensual | B7: 0.3 | C7: 0.25 | D7: 0.2 | E7: %
A8: Usuarios finales (promedio) | B8: 2000 | C8: 10000 | D8: 30000 | E8: usuarios
A10: CRECIMIENTO DE ABOGADOS
A11: Métrica | B11: Año 1 | C11: Año 2 | D11: Año 3 | E11: Unidad
A12: Abogados iniciales | B12: 20 | C12: 100 | D12: 500 | E12: abogados
A13: Crecimiento mensual | B13: 0.15 | C13: 0.2 | D13: 0.15 | E13: %
A14: Abogados finales (promedio) | B14: 100 | C14: 500 | D14: 1000 | E14: abogados
A16: TASAS DE CONVERSIÓN
A17: Métrica | B17: Tasa | C17: Descripción
A18: IA → Request Lawyer | B18: 0.2 | C18: Usuarios que piden abogado
A19: Request → Hire | B19: 0.5 | C19: Requests que contratan
A20: Overall Conversion | B20: 0.1 | C20: Usuario → Cliente pagador
A21: Usuarios → Servicios Auto Y1 | B21: 0.1 | C21: Conversión servicios automatizados
A22: Usuarios → Servicios Auto Y2 | B22: 0.15
A23: Usuarios → Servicios Auto Y3 | B23: 0.2
A26: PRECIOS (USD)
A27: Concepto | B27: Precio USD | C27: Notas
A28: Honorario promedio abogado | B28: 389 | C28: CLP $350,000
A29: Comisión JusticiaAI | B29: 0.25 | C29: 25% de honorario
A30: Ingreso por caso | B30: 97 | C30: $389 × 25%
A31: Servicio automatizado | B31: 22 | C31: CLP $20,000
A32: B2B empresa/mes | B32: 444 | C32: CLP $400,000
A33: Suscripción Free | B33: 0
A34: Suscripción Profesional | B34: 55 | C34: CLP $49,500
A35: Suscripción Premium | B35: 135 | C35: CLP $121,500
A36: Suscripción Firma | B36: 330 | C36: CLP $297,000
A39: MIX DE SUSCRIPCIONES ABOGADOS
A40: Plan | B40: Año 1 | C40: Año 2 | D40: Año 3 | E40: Precio
A41: Free | B41: 0.6 | C41: 0.5 | D41: 0.4 | E41: 0
A42: Profesional | B42: 0.3 | C42: 0.35 | D42: 0.45 | E42: 55
A43: Premium | B43: 0.1 | C43: 0.13 | D43: 0.13 | E43: 135
A44: Firma | B44: 0 | C44: 0.02 | D44: 0.02 | E44: 330
A47: CUSTOMER ACQUISITION COST (CAC)
A48: Tipo | B48: Año 1 | C48: Año 2 | D48: Año 3 | E48: Unidad
A49: CAC Usuario | B49: 50 | C49: 30 | D49: 20 | E49: USD
...

Sheet Revenue Model
A1: MODELO DE INGRESOS - PROYECCIÓN 3 AÑOS
B3: Año 1 | C3: Año 2 | D3: Año 3 | E3: Fórmula
A5: STREAM 1: COMISIONES
A6: Usuarios promedio/mes | B6: =Assumptions!C8 | C6: =Assumptions!D8 | D6: =Assumptions!E8
A7: Conversión global | B7: =Assumptions!B20 | C7: =Assumptions!B20 | D7: =Assumptions!B20
A8: Casos/mes | B8: =B6*B7 | C8: =C6*C7 | D8: =D6*D7
A9: Ingreso por caso | B9: =Assumptions!B30 | C9: =Assumptions!B30 | D9: =Assumptions!B30
A10: Ingreso mensual | B10: =B8*B9 | C10: =C8*C9 | D10: =D8*D9
A11: INGRESO ANUAL COMISIONES | B11: =B10*12 | C11: =C10*12 | D11: =D10*12
A14: STREAM 2: SUSCRIPCIONES ABOGADOS
A15: Total abogados | B15: =Assumptions!C14 | C15: =Assumptions!D14 | D15: =Assumptions!E14
A16: % Free (0 USD) | B16: =Assumptions!B41 | C16: =Assumptions!C41 | D16: =Assumptions!D41
A17: % Profesional (55 USD) | B17: =Assumptions!B42 | C17: =Assumptions!C42 | D17: =Assumptions!D42
A18: % Premium (135 USD) | B18: =Assumptions!B43 | C18: =Assumptions!C43 | D18: =Assumptions!D43
A19: % Firma (330 USD) | B19: =Assumptions!B44 | C19: =Assumptions!C44 | D19: =Assumptions!D44
A20: MRR Suscripciones | B20: =(B15*B17*Assumptions!E42)+(B15*B18*Assumptions!E43)+(B15*B19*Assumptions!E44) | C20: =(C15*C17*Assumptions!E42)+(C15*C18*Assumptions!E43)+(C15*C19*Assumptions!E44) | D20: =(D15*D17*Assumptions!E42)+(D15*D18*Assumptions!E43)+(D15*D19*Assumptions!E44)
A21: INGRESO ANUAL SUSCRIPCIONES | B21: =B20*12 | C21: =C20*12 | D21: =D20*12
A24: STREAM 3: SERVICIOS AUTOMATIZADOS
A25: Usuarios promedio/mes | B25: =Assumptions!C8 | C25: =Assumptions!D8 | D25: =Assumptions!E8
A26: Conversión servicios | B26: =Assumptions!B21 | C26: =Assumptions!B22 | D26: =Assumptions!B23
A27: Servicios vendidos/mes | B27: =B25*B26 | C27: =C25*C26 | D27: =D25*D26
A28: Precio servicio | B28: =Assumptions!B31 | C28: =Assumptions!B31 | D28: =Assumptions!B31
A29: INGRESO ANUAL AUTOMATIZADOS | B29: =B27*B28*12 | C29: =C27*C28*12 | D29: =D27*D28*12
A32: STREAM 4: B2B CORPORATIVO
A33: Empresas clientes | B33: =Assumptions!B55 | C33: =Assumptions!C55 | D33: =Assumptions!D55
A34: Precio mensual | B34: =Assumptions!B32 | C34: =Assumptions!B32 | D34: =Assumptions!B32
A35: INGRESO ANUAL B2B | B35: =B33*B34*12 | C35: =C33*C34*12 | D35: =D33*D34*12
A38: STREAM 5: PARTNERSHIPS
A39: INGRESO ANUAL PARTNERSHIPS | B39: =(B11+B21+B29+B35)*0.05 | C39: =(C11+C21+C29+C35)*0.05 | D39: =(D11+D21+D29+D35)*0.05
A42: TOTAL REVENUE
A43: ARR (Annual Recurring Revenue) | B43: =B11+B21+B29+B35+B39 | C43: =C11+C21+C29+C35+C39 | D43: =D11+D21+D29+D35+D39
A44: MRR (Monthly Recurring Revenue) | B44: =B43/12 | C44: =C43/12 | D44: =D43/12
A45: Growth YoY | B45: - | C45: =(C43-B43)/B43 | D45: =(D43-C43)/C43

Sheet Unit Economics
A1: UNIT ECONOMICS
B3: Año 1 | C3: Año 2 | D3: Año 3 | E3: Target
A5: CUSTOMER (USUARIO QUE PAGA)
A6: CAC (Customer Acquisition Cost) | B6: =Assumptions!B49 | C6: =Assumptions!C49 | D6: =Assumptions!D49 | E6: < $30
A7: LTV (Lifetime Value) | B7: 50 | C7: 50 | D7: 50 | E7: > $150
A8: LTV/CAC Ratio | B8: =B7/B6 | C8: =C7/C6 | D8: =D7/D6 | E8: > 3.0x
A9: Payback Period (meses) | B9: 12 | C9: 7 | D9: 5 | E9: < 12
A10: Gross Margin | B10: =1-Assumptions!B61 | C10: =1-Assumptions!C61 | D10: =1-Assumptions!D61 | E10: > 70%
A13: ABOGADO (SUPPLY SIDE)
A14: CAC Abogado | B14: =Assumptions!B50 | C14: =Assumptions!C50 | D14: =Assumptions!D50 | E14: < $250
A15: Permanencia (años) | B15: 3 | C15: 3 | D15: 3 | E15: > 2
A16: Casos generados (total) | B16: =B15*8 | C16: =C15*8 | D16: =D15*8
A17: Comisiones generadas | B17: =B16*Assumptions!B30 | C17: =C16*Assumptions!B30 | D17: =D16*Assumptions!B30
A18: Suscripción promedio/mes | B18: 55 | C18: 55 | D18: 55
A19: Suscripciones totales | B19: =B18*B15*12 | C19: =C18*C15*12 | D19: =D18*D15*12
A20: LTV Total Abogado | B20: =B17+B19 | C20: =C17+C19 | D20: =D17+D19 | E20: > $3,000
A21: LTV/CAC Abogado | B21: =B20/B14 | C21: =C20/C14 | D21: =D20/D14 | E21: > 10x
A24: CONCLUSIÓN
A25: Supply side (abogados) es MUY rentable con LTV/CAC de 21.5x ✅
A26: Demand side (usuarios) mejora con escala, alcanzando 2.5x en Año 3 ✅

Sheet P&L
A1: P&L - INCOME STATEMENT (3 AÑOS)
B3: Año 1 | C3: Año 2 | D3: Año 3
A5: REVENUE
A6: Comisiones | B6: ='Revenue Model'!B11 | C6: ='Revenue Model'!C11 | D6: ='Revenue Model'!D11
A7: Suscripciones | B7: ='Revenue Model'!B21 | C7: ='Revenue Model'!C21 | D7: ='Revenue Model'!D21
A8: Automatizados | B8: ='Revenue Model'!B29 | C8: ='Revenue Model'!C29 | D8: ='Revenue Model'!D29
A9: B2B | B9: ='Revenue Model'!B35 | C9: ='Revenue Model'!C35 | D9: ='Revenue Model'!D35
A10: Partnerships | B10: ='Revenue Model'!B39 | C10: ='Revenue Model'!C39 | D10: ='Revenue Model'!D39
A12: Total Revenue | B12: =SUM(B6:B10) | C12: =SUM(C6:C10) | D12: =SUM(D6:D10)
A15: COGS
A16: Total COGS | B16: =B12*Assumptions!B61 | C16: =C12*Assumptions!C61 | D16: =D12*Assumptions!D61
A18: Gross Profit | B18: =B12-B16 | C18: =C12-C16 | D18: =D12-D16
A19: Gross Margin | B19: =B18/B12 | C19: =C18/C12 | D19: =D18/D12
A22: OPERATING EXPENSES
A23: R&D | B23: =B12*Assumptions!B62 | C23: =C12*Assumptions!C62 | D23: =D12*Assumptions!D62
A24: S&M (Sales & Marketing) | B24: =B12*Assumptions!B63 | C24: =C12*Assumptions!C63 | D24: =D12*Assumptions!D63
A25: G&A (General & Admin) | B25: =B12*Assumptions!B64 | C25: =C12*Assumptions!C64 | D25: =D12*Assumptions!D64
A27: Total OpEx | B27: =SUM(B23:B25) | C27: =SUM(C23:C25) | D27: =SUM(D23:D25)
A30: EBITDA | B30: =B18-B27 | C30: =C18-C27 | D30: =D18-D27
A31: EBITDA Margin | B31: =B30/B12 | C31: =C30/C12 | D31: =D30/D12
A34: Depreciation | B34: 0 | C34: 5000 | D34: 15000
A35: Interest | B35: 0 | C35: 0 | D35: 0
A37: Net Income | B37: =B30-B34-B35 | C37: =C30-C34-C35 | D37: =D30-D34-D35
A38: Net Margin | B38: =B37/B12 | C38: =C37/C12 | D38: =D37/D12

Sheet Cash Flow
A1: CASH FLOW STATEMENT
B3: Año 1 | C3: Año 2 | D3: Año 3
A5: OPERATING ACTIVITIES
A6: Net Income | B6: ='P&L'!B37 | C6: ='P&L'!C37 | D6: ='P&L'!D37
A7: + Depreciation | B7: ='P&L'!B34 | C7: ='P&L'!C34 | D7: ='P&L'!D34
A9: Cash from Operations | B9: =B6+B7 | C9: =C6+C7 | D9: =D6+D7
A12: INVESTING ACTIVITIES
A13: CapEx | B13: -10000 | C13: -30000 | D13: -100000
A15: Cash from Investing | B15: =B13 | C15: =C13 | D15: =D13
A18: FINANCING ACTIVITIES
A19: Equity Raised | B19: =Assumptions!B69 | C19: 0 | D19: 0
A20: Debt Raised | B20: 0 | C20: 0 | D20: 0
A22: Cash from Financing | B22: =B19+B20 | C22: =C19+C20 | D22: =D19+D20
A25: NET CASH FLOW | B25: =B9+B15+B22 | C25: =C9+C15+C22 | D25: =D9+D15+D22
A28: CASH BALANCE
A29: Beginning Cash | B29: 0 | C29: =B30 | D29: =C30
A30: Ending Cash | B30: =B29+B25 | C30: =C29+C25 | D30: =D29+D25
A32: Monthly Burn Rate | B32: =(B9+B15)/12 | C32: =(C9+C15)/12 | D32: =(D9+D15)/12
A33: Runway (meses) | B33: =IF(B32<0, B30/ABS(B32), "Infinito") | C33: =IF(C32<0, C30/ABS(C32), "Infinito") | D33: =IF(D32<0, D30/ABS(D32), "Infinito")

Sheet Scenarios
A1: ANÁLISIS DE ESCENARIOS
A3: PROYECCIONES ARR POR ESCENARIO
A4: Año | B4: Pesimista (70%) | C4: Base (100%) | D4: Optimista (150%) | E4: Notas
A5: Año 1 | B5: ='Revenue Model'!B43*0.7 | C5: ='Revenue Model'!B43 | D5: ='Revenue Model'!B43*1.5 | E5: Setup inicial
A6: Año 2 | B6: ='Revenue Model'!C43*0.7 | C6: ='Revenue Model'!C43 | D6: ='Revenue Model'!C43*1.5 | E6: Tracción temprana
A7: Año 3 | B7: ='Revenue Model'!D43*0.7 | C7: ='Revenue Model'!D43 | D7: ='Revenue Model'!D43*1.5 | E7: Escala completa
A10: ANÁLISIS DE SENSIBILIDAD (Año 3)
A11: Variable | B11: Cambio | C11: Impacto ARR | D11: Nuevo ARR
A12: Base case | B12: 0% | C12: $0 | D12: ='Revenue Model'!D43
A13: Usuarios +10% | B13: +10% | C13: ='Revenue Model'!D43*0.10 | D13: ='Revenue Model'!D43*1.10
A14: Usuarios -10% | B14: -10% | C14: ='Revenue Model'!D43*(-0.10) | D14: ='Revenue Model'!D43*0.90
A15: Precio servicios +20% | B15: +20% | C15: ='Revenue Model'!D29*0.20 | D15: ='Revenue Model'!D43+C15
A16: Precio servicios -20% | B16: -20% | C16: ='Revenue Model'!D29*(-0.20) | D16: ='Revenue Model'!D43+C16
A20: PRINCIPALES RIESGOS Y MITIGACIÓN
A21: Riesgo | B21: Probabilidad | C21: Impacto | D21: Mitigación
A22: Adquisición usuarios lenta | B22: Media | C22: Alto | D22: Aumentar S&M budget, partnerships
A23: Regulación legal restrictiva | B23: Baja | C23: Alto | D23: Disclaimer claro, no asesoría legal
A24: Competencia agresiva | B24: Alta | C24: Medio | D24: Focus en IA diferenciada
A25: Costos API Claude suben | B25: Media | C25: Medio | D25: Optimizar prompts, caché, modelos
A26: Churn abogados alto | B26: Media | C26: Alto | D26: Programa de éxito, comunidad
